<?xml version='1.0'?>

<robot name="my_robot">

  <link name='chassis'>
    <pose>0 0 0.1 0 0 0</pose>

    <inertial>
      <mass value="150.0"/>
      <origin xyz="0.0 0 0" rpy=" 0 0 0"/>
      <inertia
          ixx="0.1" ixy="0" ixz="0"
          iyy="0.1" iyz="0"
          izz="0.1"
      />
    </inertial>

    <collision name='collision'>
      <origin xyz="0 0 0.1" rpy=" 0 0 0"/> 
      <geometry>
        <box size="1.4 1.4 1.1"/>
      </geometry>
    </collision>

    <visual name='chassis_visual'>
      <origin xyz="0 0 0.1" rpy=" 0 0 0"/>
      <geometry>
        <box size="1.4 1.2 1"/>
      </geometry>
      <material name="yellow"> 
        <color rgba="0.8 0.8 0.1 1"/>
      </material>

    </visual>


    <collision name='back_caster_collision'>
      <origin xyz="-0.55 0 -0.35" rpy=" 0 0 0"/>
      <geometry>
        <sphere radius="0.1"/>
      </geometry>
    </collision>

    <visual name='back_caster_visual'>
      <origin xyz="-0.55 0 -0.35" rpy=" 0 0 0"/>
      <geometry>
        <sphere radius="0.1"/>
      </geometry>
    </visual>

    <collision name='front_caster_collision'>
      <origin xyz="0.55 0 -0.35" rpy=" 0 0 0"/>
      <geometry>
        <sphere radius="0.1"/>
      </geometry>
    </collision>

    <visual name='front_caster_visual'>
      <origin xyz="0.55 0 -0.35" rpy=" 0 0 0"/>
      <geometry>
        <sphere radius="0.1"/>
      </geometry>
    </visual>
  </link>
  
  <link name='left_wheel'>
    <inertial>
      <mass value="5"/>
      <origin xyz="0.0 0 0" rpy=" 0 1.57 1.57"/>
      <inertia
          ixx="0.1" ixy="0" ixz="0"
          iyy="0.1" iyz="0"
          izz="0.1"
      />
    </inertial>
    
    <collision name='left_wheel_collision'>
        <origin xyz="0 0 0 " rpy=" 0 1.57 1.57"/>
        <geometry>
            <cylinder radius="0.25" length="0.07"/>
        </geometry>
    </collision>
    
    <visual name='left_wheel_visual'>
        <origin xyz="0 0 0 " rpy=" 0 1.57 1.57"/>
        <geometry>
            <cylinder radius="0.25" length="0.07"/>
        </geometry>
    </visual>
    
  </link>
  
  <link name='right_wheel'>
    <inertial>
      <mass value="5"/>
      <origin xyz="0.0 0 0" rpy=" 0 1.57 1.57"/>
      <inertia
          ixx="0.1" ixy="0" ixz="0"
          iyy="0.1" iyz="0"
          izz="0.1"
      />
    </inertial>
    
    <collision name='right_wheel_collision'>
        <origin xyz="0 0 0 " rpy=" 0 1.57 1.57"/>
        <geometry>
            <cylinder radius="0.25" length="0.07"/>
        </geometry>
    </collision>
    
    <visual name='right_wheel_visual'>
        <origin xyz="0 0 0 " rpy=" 0 1.57 1.57"/>
        <geometry>
            <cylinder radius="0.25" length="0.07"/>
        </geometry>
    </visual>
    
  </link>
  
  <link name='fork'>
    <inertial>
      <mass value=".5"/>
      <origin xyz="0.0 0 0" rpy=" 0 0 0"/>
      <inertia
          ixx="0.1" ixy="0" ixz="0"
          iyy="0.1" iyz="0"
          izz="0.1"
      />
    </inertial>
    
    <collision name='fork_collision'>
        <origin xyz="0 0 0 " rpy=" 0 0 0"/>
        <geometry>
            <box size="0.7, 0.4, 0.05"/>
        </geometry>
    </collision>
    
    <visual name='fork_visual'>
        <origin xyz="0 0 0 " rpy=" 0 0 0"/>
        <geometry>
            <box size="0.7, 0.4, 0.05"/>
        </geometry>
    </visual>
    
  </link>
   

  <joint type="continuous" name="left_wheel_hinge">
    <origin xyz="0.1 0.65 -0.2" rpy="0 0 0"/>
    <child link="left_wheel"/>
    <parent link="chassis"/>
    <axis xyz="0 1 0" rpy="0 0 0"/>
    <limit effort="10000" velocity="1000"/>
    <dynamics damping="1.0" friction="1.0"/>
  </joint>  

  <joint type="continuous" name="right_wheel_hinge">
    <origin xyz="0.1 -0.65 -0.2" rpy="0 0 0"/>
    <child link="right_wheel"/>
    <parent link="chassis"/>
    <axis xyz="0 1 0" rpy="0 0 0"/>
    <limit effort="10000" velocity="1000"/>
    <dynamics damping="1.0" friction="1.0"/>
  </joint>
      
  <joint type="prismatic" name="lifter">
    <origin xyz="1.1 0 -0.3" rpy="0 0 0"/>
    <child link="fork"/>
    <parent link="chassis"/>
    <axis xyz="0 0 1"/>
    <limit lower="-0.04" upper="0.2"/>
    <dynamics damping="1.0" friction="1.0"/>
  </joint>
  
</robot> 
